<robot name="box_car">、
    <!-- 设置一个原点(机器人中心点的投影) -->
    <link name="base_footprint">
        <visual>
            <geometry>
                <sphere radius="0.001" />
            </geometry>
        </visual>
    </link>
    <!-- 底盘 -->
    <link name="base_link">
        <visual>
            <geometry>
                <!-- box cylinder sphere mesh -->
                <box size="0.5 0.2 0.1" />
            </geometry>
            <origin xyz="0 0 0" rpy="0 0 0" />
            <material name="yellow">
                <color rgba="0.7 0.5 0 0.5" />
            </material>
        </visual>
    </link>
    <!-- 摄像头 -->
    <link name="camera">
        <visual>
            <geometry>
                <box size="0.02 0.05 0.05" />
            </geometry>
            <origin xyz="0 0 0" rpy="0 0 0" />
            <material name="red">
                <color rgba="1 0 0 0.5" />
            </material>
        </visual>
    </link>
    <!-- 底盘与原点连接的关节（好处是后面不用考虑原点link转换关系了） -->
    <joint name="base_link2base_footprint" type="fixed">
        <parent link="base_footprint" />
        <child link="base_link" />
        <!-- 如果有初始偏移，写在footprint里方便 -->
        <origin xyz="0 0 0.05" rpy="0 0 1.57" />
    </joint>
    <!-- 摄像头与底盘连接的关节（代表关节之间转换关系，添加发布节点才生效） -->
    <joint name="camera2baselink" type="continuous">
        <parent link="base_link"/>
        <child link="camera" />
        <!-- 需要计算两个 link 的物理中心之间的偏移量 -->
        <!-- 两个link的base link的转换关系，无视origin参数 -->
        <origin xyz="0.2 0 0.175" rpy="0 0 0" />
        <!-- 设置关节旋转的坐标系 -->
        <axis xyz="0 0 1" />
    </joint>
</robot>

